<robot name="robot">
<!-- This URDF file was automatically generated by onshape-to-robot! Created by
Grégoire Passault (https://github.com/Gregwar) -->
    <link name="world"/>

    <joint name="world_parte-interior_joint" type="fixed">
        <parent link="world"/>
        <child link="parte_interior"/>
        <origin xyz="0.0 0.0 0.0" rpy="0.0 0.0 0.0"/>
    </joint>

    <link name="parte_interior">
        <visual>
            <origin xyz="-0.17157259699105301132 0.24287593199312426662 0.28583529680976227372" rpy="3.141592653589793116 -2.4651903288156597024e-31 3.141592653589793116" />
            <geometry>
                <mesh filename="package://theta_description/meshes/estrutura_esquerda.stl"/>
            </geometry>
            <material name="estrutura_esquerda_material">
                <color rgba="0.61568627450980395466 0.81176470588235294379 0.92941176470588238168 1.0"/>
            </material>
        </visual>
        <collision>
            <origin xyz="-0.17157259699105301132 0.24287593199312426662 0.28583529680976227372" rpy="3.141592653589793116 -2.4651903288156597024e-31 3.141592653589793116" />
            <geometry>
                <mesh filename="package://theta_description/meshes/estrutura_esquerda.stl"/>
            </geometry>
        </collision>
        <visual>
            <origin xyz="-0.15164718061608356559 -0.063263104190967395235 -0.067790648939520817273" rpy="0 -0 -2.3592239273284576484e-16" />
            <geometry>
                <mesh filename="package://theta_description/meshes/suporte_bateria.stl"/>
            </geometry>
            <material name="suporte_bateria_material">
                <color rgba="0.61568627450980395466 0.81176470588235294379 0.92941176470588238168 1.0"/>
            </material>
        </visual>
        <collision>
        <origin xyz="-0.15164718061608356559 -0.063263104190967395235 -0.067790648939520817273" rpy="0 -0 -2.3592239273284576484e-16" />
        <geometry>
        <mesh filename="package://theta_description/meshes/suporte_bateria.stl"/>
        </geometry>
        </collision>
        <visual>
        <origin xyz="-0.18777259699105303126 0.21037593199312421 0.00683529680976174836" rpy="2.4651903288156575129e-31 -1.35393051783555648e-16 1.570796326794896336" />
        <geometry>
        <mesh filename="package://theta_description/meshes/encaixeeixo.stl"/>
        </geometry>
        <material name="encaixeeixo_material">
        <color rgba="0.61568627450980395466 0.81176470588235294379 0.92941176470588238168 1.0"/>
        </material>
        </visual>
        <collision>
        <origin xyz="-0.18777259699105303126 0.21037593199312421 0.00683529680976174836" rpy="2.4651903288156575129e-31 -1.35393051783555648e-16 1.570796326794896336" />
        <geometry>
        <mesh filename="package://theta_description/meshes/encaixeeixo.stl"/>
        </geometry>
        </collision>
        <visual>
        <origin xyz="-0.17157259699105312234 -0.21462406800687613972 0.32583529680976230924" rpy="0 1.2246467991473549328e-16 6.8001160258290847962e-16" />
        <geometry>
        <mesh filename="package://theta_description/meshes/alça_esquerda.stl"/>
        </geometry>
        <material name="alça_esquerda_material">
        <color rgba="0.64705882352941179736 0.64705882352941179736 0.64705882352941179736 1.0"/>
        </material>
        </visual>
        <collision>
        <origin xyz="-0.17157259699105312234 -0.21462406800687613972 0.32583529680976230924" rpy="0 1.2246467991473549328e-16 6.8001160258290847962e-16" />
        <geometry>
        <mesh filename="package://theta_description/meshes/alça_esquerda.stl"/>
        </geometry>
        </collision>
        <visual>
        <origin xyz="0.21956962733279611344 0.24237593199312440495 -0.024687850027610480641" rpy="0 -0 0" />
        <geometry>
        <mesh filename="package://theta_description/meshes/eixorodamenor.stl"/>
        </geometry>
        <material name="eixorodamenor_material">
        <color rgba="0.61568627450980395466 0.81176470588235294379 0.92941176470588238168 1.0"/>
        </material>
        </visual>
        <collision>
        <origin xyz="0.21956962733279611344 0.24237593199312440495 -0.024687850027610480641" rpy="0 -0 0" />
        <geometry>
        <mesh filename="package://theta_description/meshes/eixorodamenor.stl"/>
        </geometry>
        </collision>
        <visual>
        <origin xyz="0.16085281938391673973 0.1965368958090327467 0.057486351060479119746" rpy="-1.2246467991473556724e-16 1.35393051783555648e-16 -1.57079632679489678" />
        <geometry>
        <mesh filename="package://theta_description/meshes/caixacentral.stl"/>
        </geometry>
        <material name="caixacentral_material">
        <color rgba="0.61568627450980395466 0.81176470588235294379 0.92941176470588238168 1.0"/>
        </material>
        </visual>
        <collision>
        <origin xyz="0.16085281938391673973 0.1965368958090327467 0.057486351060479119746" rpy="-1.2246467991473556724e-16 1.35393051783555648e-16 -1.57079632679489678" />
        <geometry>
        <mesh filename="package://theta_description/meshes/caixacentral.stl"/>
        </geometry>
        </collision>
        <visual>
        <origin xyz="0.18786962733279607973 0.24287593199312432213 0.28638089662856930362" rpy="3.141592653589793116 -0 -3.1415926535897926719" />
        <geometry>
        <mesh filename="package://theta_description/meshes/estrutura_direita.stl"/>
        </geometry>
        <material name="estrutura_direita_material">
        <color rgba="0.61568627450980395466 0.81176470588235294379 0.92941176470588238168 1.0"/>
        </material>
        </visual>
        <collision>
        <origin xyz="0.18786962733279607973 0.24287593199312432213 0.28638089662856930362" rpy="3.141592653589793116 -0 -3.1415926535897926719" />
        <geometry>
        <mesh filename="package://theta_description/meshes/estrutura_direita.stl"/>
        </geometry>
        </collision>
        <visual>
        <origin xyz="0.18786962733279638504 -0.21462406800687591768 0.32638089662856933915" rpy="0 6.1629758220391519929e-33 6.8001160258290847962e-16" />
        <geometry>
        <mesh filename="package://theta_description/meshes/alça_direita.stl"/>
        </geometry>
        <material name="alça_direita_material">
        <color rgba="0.61568627450980395466 0.81176470588235294379 0.92941176470588238168 1.0"/>
        </material>
        </visual>
        <collision>
        <origin xyz="0.18786962733279638504 -0.21462406800687591768 0.32638089662856933915" rpy="0 6.1629758220391519929e-33 6.8001160258290847962e-16" />
        <geometry>
        <mesh filename="package://theta_description/meshes/alça_direita.stl"/>
        </geometry>
        </collision>
        <visual>
        <origin xyz="-0.20846361847784078414 0.23037593199312422776 -0.11226164164693730463" rpy="-1.570796326794896558 1.570796326794896558 0" />
        <geometry>
        <mesh filename="package://theta_description/meshes/pneumenor.stl"/>
        </geometry>
        <material name="pneumenor_material">
        <color rgba="0.61568627450980395466 0.81176470588235294379 0.92941176470588238168 1.0"/>
        </material>
        </visual>
        <collision>
        <origin xyz="-0.20846361847784078414 0.23037593199312422776 -0.11226164164693730463" rpy="-1.570796326794896558 1.570796326794896558 0" />
        <geometry>
        <mesh filename="package://theta_description/meshes/pneumenor.stl"/>
        </geometry>
        </collision>
        <visual>
        <origin xyz="0.2143786058460082633 0.23037593199312433878 -0.11171604182813017758" rpy="-1.570796326794896558 1.570796326794896558 0" />
        <geometry>
        <mesh filename="package://theta_description/meshes/pneumenor.stl"/>
        </geometry>
        <material name="pneumenor_material">
        <color rgba="0.61568627450980395466 0.81176470588235294379 0.92941176470588238168 1.0"/>
        </material>
        </visual>
        <collision>
        <origin xyz="0.2143786058460082633 0.23037593199312433878 -0.11171604182813017758" rpy="-1.570796326794896558 1.570796326794896558 0" />
        <geometry>
        <mesh filename="package://theta_description/meshes/pneumenor.stl"/>
        </geometry>
        </collision>
        <visual>
        <origin xyz="0.20406962733279609967 0.25037593199312435654 0.0073808966285689309172" rpy="0 -0 -1.5707963267948958919" />
        <geometry>
        <mesh filename="package://theta_description/meshes/encaixeeixo.stl"/>
        </geometry>
        <material name="encaixeeixo_material">
        <color rgba="0.61568627450980395466 0.81176470588235294379 0.92941176470588238168 1.0"/>
        </material>
        </visual>
        <collision>
        <origin xyz="0.20406962733279609967 0.25037593199312435654 0.0073808966285689309172" rpy="0 -0 -1.5707963267948958919" />
        <geometry>
        <mesh filename="package://theta_description/meshes/encaixeeixo.stl"/>
        </geometry>
        </collision>
        <visual>
        <origin xyz="-0.203272596991052934 0.24237593199312429393 -0.025233449846417621565" rpy="0 -0 0" />
        <geometry>
        <mesh filename="package://theta_description/meshes/eixorodamenor.stl"/>
        </geometry>
        <material name="eixorodamenor_material">
        <color rgba="0.61568627450980395466 0.81176470588235294379 0.92941176470588238168 1.0"/>
        </material>
        </visual>
        <collision>
        <origin xyz="-0.203272596991052934 0.24237593199312429393 -0.025233449846417621565" rpy="0 -0 0" />
        <geometry>
        <mesh filename="package://theta_description/meshes/eixorodamenor.stl"/>
        </geometry>
        </collision>
        <inertial>
        <origin xyz="0.008170437061892257824 0.043928064197974167615 0.14489944243383257039" rpy="0 0 0"/>
        <mass value="171.94554958043747206" />
        <inertia ixx="4.3846896981672349725" ixy="0.00364880132254727374"  ixz="-0.0072407607976240715569" iyy="3.6360052698491176493" iyz="-0.53322694252760016731" izz="4.5692743191950366821" />
        </inertial>
    </link>

    <link name="rodas_maiores">
    <visual>
    <origin xyz="0 0 0" rpy="1.570796326794896558 3.1242248823380094523e-75 0" />
    <geometry>
    <mesh filename="package://theta_description/meshes/eixorodamaior.stl"/>
    </geometry>
    <material name="eixorodamaior_material">
    <color rgba="0.61568627450980395466 0.81176470588235294379 0.92941176470588238168 1.0"/>
    </material>
    </visual>
    <collision>
    <origin xyz="0 0 0" rpy="1.570796326794896558 3.1242248823380094523e-75 0" />
    <geometry>
    <mesh filename="package://theta_description/meshes/eixorodamaior.stl"/>
    </geometry>
    </collision>
    <visual>
    <origin xyz="0 0 -0.059100000000000069145" rpy="-1.570796326794896558 2.4492935982946985257e-16 -3.141592653589793116" />
    <geometry>
    <mesh filename="package://theta_description/meshes/rodamaior.stl"/>
    </geometry>
    <material name="rodamaior_material">
    <color rgba="0.61568627450980395466 0.81176470588235294379 0.92941176470588238168 1.0"/>
    </material>
    </visual>
    <collision>
    <origin xyz="0 0 -0.059100000000000069145" rpy="-1.570796326794896558 2.4492935982946985257e-16 -3.141592653589793116" />
    <geometry>
    <mesh filename="package://theta_description/meshes/rodamaior.stl"/>
    </geometry>
    </collision>
    <inertial>
    <origin xyz="1.2653899499277690085e-07 3.213148670797778341e-06 -0.058590622625737491525" rpy="0 0 0"/>
    <mass value="11.932094458693160988" />
    <inertia ixx="0.080324749708183040831" ixy="-2.0803509752194626826e-11"  ixz="-2.1421984032297167469e-07" iyy="0.080321467239751184741" iyz="-1.8319399352921136127e-06" izz="0.15479264107262497019" />
    </inertial>
    </link>

    <joint name="rodaDirMaior" type="continuous">
    <origin xyz="0.18760281938391643042 -0.26726310419096743765 -0.027790648939520816441" rpy="-1.570796326794896558 -5.1463765465983115601e-30 1.570796326794896336" />
    <parent link="parte_interior" />
    <child link="rodas_maiores" />
    <axis xyz="0 0 1"/>
    <limit effort="1" velocity="20" />
    <joint_properties friction="0.0"/>
    </joint>

    <link name="rodas_maiores_2">
    <visual>
    <origin xyz="0 0 0" rpy="1.570796326794896558 -0 0" />
    <geometry>
    <mesh filename="package://theta_description/meshes/eixorodamaior.stl"/>
    </geometry>
    <material name="eixorodamaior_material">
    <color rgba="0.61568627450980395466 0.81176470588235294379 0.92941176470588238168 1.0"/>
    </material>
    </visual>
    <collision>
    <origin xyz="0 0 0" rpy="1.570796326794896558 -0 0" />
    <geometry>
    <mesh filename="package://theta_description/meshes/eixorodamaior.stl"/>
    </geometry>
    </collision>
    <visual>
    <origin xyz="0 0 -0.059100000000000069145" rpy="-1.570796326794896558 -0 3.141592653589793116" />
    <geometry>
    <mesh filename="package://theta_description/meshes/rodamaior.stl"/>
    </geometry>
    <material name="rodamaior_material">
    <color rgba="0.61568627450980395466 0.81176470588235294379 0.92941176470588238168 1.0"/>
    </material>
    </visual>
    <collision>
    <origin xyz="0 0 -0.059100000000000069145" rpy="-1.570796326794896558 -0 3.141592653589793116" />
    <geometry>
    <mesh filename="package://theta_description/meshes/rodamaior.stl"/>
    </geometry>
    </collision>
    <inertial>
    <origin xyz="1.2653899499284487524e-07 3.213148670797778341e-06 -0.058590622625737491525" rpy="0 0 0"/>
    <mass value="11.932094458693160988" />
    <inertia ixx="0.080324749708183040831" ixy="-2.0803509752071838972e-11"  ixz="-2.1421984030469259781e-07" iyy="0.080321467239751184741" iyz="-1.8319399352921136127e-06" izz="0.15479264107262497019" />
    </inertial>
    </link>

    <joint name="rodaEsqMaior" type="continuous">
    <origin xyz="-0.17089718061608361044 -0.26726310419096732662 -0.027790648939520816441" rpy="-1.570796326794896558 -0 -1.57079632679489678" />
    <parent link="parte_interior" />
    <child link="rodas_maiores_2" />
    <axis xyz="0 0 1"/>
    <limit effort="1" velocity="20" />
    <joint_properties friction="0.0"/>
    </joint>


</robot>
